<sdf version="1.6">
  <model name="payload">
    <pose>0 0 0.5 0 0 0</pose>
    <link name="link_00">
      <pose>0.0 0 0 0 0 0</pose>
      <collision name="collision_00">
        <geometry>
          <sphere>
            <radius>0.5</radius>
          </sphere>
        </geometry>
      </collision>
      <visual name="visual_00">
        <geometry>
          <sphere>
            <radius>0.5</radius>
          </sphere>
        </geometry>
      </visual>
    </link>
      <joint name="joint_00" type="revolute">
        <parent>payload</parent>
        <child>firefly::link3</child>
        <pose>0.0 0.0 0.0 0.0 0.0 0.0</pose>
        <axis>
          <xyz>1.0 0.0 0.0</xyz>
        </axis>
      </joint>


</sdf>
