<?xml version="1.0" ?>
<!-- =================================================================================== -->
<!-- | This document was autogenerated by xacro from /home/ismailupro4/catkin_ws/src/rotors_simulator/rotors_description/urdf/firefly_formation.xacro 
	| -->
<!-- | EDITING THIS FILE BY HAND IS NOT RECOMMENDED | -->
<!-- =================================================================================== -->
<!-- Copyright 2015 Fadri Furrer, ASL, ETH Zurich, Switzerland Copyright 
	2015 Michael Burri, ASL, ETH Zurich, Switzerland Copyright 2015 Mina Kamel, 
	ASL, ETH Zurich, Switzerland Copyright 2015 Janosch Nikolic, ASL, ETH Zurich, 
	Switzerland Copyright 2015 Markus Achtelik, ASL, ETH Zurich, Switzerland 
	Licensed under the Apache License, Version 2.0 (the "License"); you may not 
	use this file except in compliance with the License. You may obtain a copy 
	of the License at http://www.apache.org/licenses/LICENSE-2.0 Unless required 
	by applicable law or agreed to in writing, software distributed under the 
	License is distributed on an "AS IS" BASIS, WITHOUT WARRANTIES OR CONDITIONS 
	OF ANY KIND, either express or implied. See the License for the specific 
	language governing permissions and limitations under the License. LEADER 
	UAV LEADER UAV LEADER UAV LEADER UAV LEADER UAV -->
<robot name="formation" xmlns:xacro="http://ros.org/wiki/xacro">
	<!-- Macro for the inertia of a box -->
	<!-- Macro for the inertial properties of a box -->
	<!-- Main multirotor link -->
	<!-- Rotor joint and link -->
	<!-- Properties -->
	<!-- xacro:property name="namespace" value="$(arg namespace" / -->
	<!-- [kg m/s^2] -->
	<!-- [s] -->
	<!-- [s] -->
	<!-- [rad/s] -->
	<!-- arbitrary value for mass of the links of the arm -->
	<!-- Square dimensions (widthxwidth) of beams -->
	<!-- Link 1 -->
	<!-- Link 2 -->
	<!-- Link 3 -->
	<!-- Link 3 -->
	<!-- Link 3 -->
	<!-- Link 3 -->
	<!-- xacro:property name="axel_offset" value="0.005" / -->
	<!-- Space btw top of beam and the each joint -->
	<!-- Property Blocks -->
	<!-- inertia of a single rotor, assuming it is a cuboid. Height=3mm, width=15mm -->
	<!-- Macro to add logging to a bag file. -->
	<!-- Macro to add a camera. -->
	<!-- Camera joint macro - just the joints, links, and collisions for a single 
		camera. -->
	<!-- Camera sensor macro - just image parameters. -->
	<!-- Macro to add a multicamera (stereo pair). -->
	<!-- Macro to add the controller interface. -->
	<!-- Macro to add the mavlink interface. -->
	<!-- Macro to add an IMU. -->
	<!-- Macro to add a generic odometry sensor. -->
	<!-- Macro to add the wind plugin. -->
	<!-- VI sensor macros -->
	<!-- Macro to add a VI-sensor camera. -->
	<!-- Macro to add a VI-sensor stereo camera. -->
	<!-- Macro to add a depth camera on the VI-sensor. -->
	<!-- VI-Sensor Macro -->
	<link name="base_link">
		<collision>
			<origin rpy="0.0 0.0 0.0" xyz="0.0 0.0 0.0" />
			<geometry>
				<box size="0.5 3.0 0.5" />
			</geometry>
		</collision>
		<visual>
			<origin rpy="0.0 0.0 0.0" xyz="0.0 0.0 0.0" />
			<geometry>
				<box size="0.5 3.0 0.5" />
			</geometry>
			<material name="orange" />
		</visual>
		<inertial>
			<origin rpy="0.0 0.0 0.0" xyz="0.0 0.0 0.0" />
			<mass value="1.0" />
			<inertia ixx="0.01" ixy="0.0" ixz="0.0" iyy="0.01" iyz="0.0"
				izz="0.01" />
		</inertial>
	</link>
	<!-- Included URDF Files -->
	<!-- <origin xyz="${ox} ${oy} ${oz}" rpy="${ophi} ${otheta} ${opsi}" /> -->
	<!-- Instantiate multirotor_base_macro once -->
	<link name="xxx/x1/base_link" />
	<joint name="xxx/x1/base_joint" type="fixed">
		<origin rpy="0 0 0" xyz="0 0 0" />
		<parent link="xxx/x1/base_link" />
		<child link="xxx/x1/base_link_inertia" />
	</joint>
	<link name="xxx/x1/base_link_inertia">
		<inertial>
			<mass value="1.5" />
			<!-- [kg] -->
			<origin xyz="0 0 0" />
			<inertia ixx="0.0347563" ixy="0.0" ixz="0.0" iyy="0.0458929"
				iyz="0.0" izz="0.0977" />
		</inertial>
		<visual>
			<origin rpy="0 0 0" xyz="0 0 0" />
			<geometry>
				<mesh filename="package://rotors_description/meshes/firefly.dae"
					scale="1 1 1" />
			</geometry>
		</visual>
		<collision>
			<origin rpy="0 0 0" xyz="0 0 0" />
			<geometry>
				<box size="0.1 0.1 0.16" />
				<!-- [m] [m] [m] -->
			</geometry>
		</collision>
	</link>
	<!-- Instantiate rotors -->
	<joint name="xxx/rotor_0_joint" type="continuous">
		<origin rpy="0 0    0" xyz="0.186195461814 0.1075 0.037" />
		<axis xyz="0 0 1" />
		<!-- TODO(ff): not currently set because it's not yet supported -->
		<!-- <limit effort="2000" velocity="${max_rot_velocity}" /> -->
		<parent link="xxx/x1/base_link" />
		<child link="xxx/rotor_0" />
	</joint>
	<link name="xxx/rotor_0">
		<inertial>
			<mass value="0.005" />
			<!-- [kg] -->
			<inertia ixx="9.7499961e-07" ixy="0.0" ixz="0.0" iyy="4.1704149985e-05"
				iyz="0.0" izz="4.2604149625e-05" />
		</inertial>
		<visual>
			<geometry>
				<!-- <cylinder length="0.5" radius="${radius_rotor}"/> -->
				<!-- [m] -->
				<mesh filename="package://rotors_description/meshes/propeller_ccw.dae"
					scale="0.1 0.1 0.1" />
				<!-- The propeller meshes have a radius of 1m -->
				<!-- <box size="${2*radius_rotor} 0.01 0.005"/> -->
			</geometry>
		</visual>
		<collision>
			<geometry>
				<cylinder length="0.05" radius="0.1" />
				<!-- [m] -->
			</geometry>
		</collision>
	</link>
	<gazebo>
		<plugin filename="librotors_gazebo_motor_model.so" name="xxx_front_left_motor_model">
			<robotNamespace>xxx</robotNamespace>
			<jointName>xxx/rotor_0_joint</jointName>
			<linkName>xxx/rotor_0</linkName>
			<turningDirection>ccw</turningDirection>
			<timeConstantUp>0.0125</timeConstantUp>
			<timeConstantDown>0.025</timeConstantDown>
			<maxRotVelocity>838</maxRotVelocity>
			<motorConstant>8.54858e-06</motorConstant>
			<momentConstant>0.016</momentConstant>
			<commandSubTopic>gazebo/command/motor_speed</commandSubTopic>
			<motorNumber>0</motorNumber>
			<rotorDragCoefficient>8.06428e-05</rotorDragCoefficient>
			<rollingMomentCoefficient>1e-06</rollingMomentCoefficient>
			<motorSpeedPubTopic>motor_speed/0</motorSpeedPubTopic>
			<rotorVelocitySlowdownSim>10</rotorVelocitySlowdownSim>
		</plugin>
	</gazebo>
	<gazebo reference="xxx/rotor_0">
		<material>Gazebo/Red</material>
	</gazebo>
	<joint name="xxx/rotor_1_joint" type="continuous">
		<origin rpy="0 0 0" xyz="0 0.215 0.037" />
		<axis xyz="0 0 1" />
		<!-- TODO(ff): not currently set because it's not yet supported -->
		<!-- <limit effort="2000" velocity="${max_rot_velocity}" /> -->
		<parent link="xxx/x1/base_link" />
		<child link="xxx/rotor_1" />
	</joint>
	<link name="xxx/rotor_1">
		<inertial>
			<mass value="0.005" />
			<!-- [kg] -->
			<inertia ixx="9.7499961e-07" ixy="0.0" ixz="0.0" iyy="4.1704149985e-05"
				iyz="0.0" izz="4.2604149625e-05" />
		</inertial>
		<visual>
			<geometry>
				<!-- <cylinder length="0.5" radius="${radius_rotor}"/> -->
				<!-- [m] -->
				<mesh filename="package://rotors_description/meshes/propeller_cw.dae"
					scale="0.1 0.1 0.1" />
				<!-- The propeller meshes have a radius of 1m -->
				<!-- <box size="${2*radius_rotor} 0.01 0.005"/> -->
			</geometry>
		</visual>
		<collision>
			<geometry>
				<cylinder length="0.05" radius="0.1" />
				<!-- [m] -->
			</geometry>
		</collision>
	</link>
	<gazebo>
		<plugin filename="librotors_gazebo_motor_model.so" name="xxx_left_motor_model">
			<robotNamespace>xxx</robotNamespace>
			<jointName>xxx/rotor_1_joint</jointName>
			<linkName>xxx/rotor_1</linkName>
			<turningDirection>cw</turningDirection>
			<timeConstantUp>0.0125</timeConstantUp>
			<timeConstantDown>0.025</timeConstantDown>
			<maxRotVelocity>838</maxRotVelocity>
			<motorConstant>8.54858e-06</motorConstant>
			<momentConstant>0.016</momentConstant>
			<commandSubTopic>gazebo/command/motor_speed</commandSubTopic>
			<motorNumber>1</motorNumber>
			<rotorDragCoefficient>8.06428e-05</rotorDragCoefficient>
			<rollingMomentCoefficient>1e-06</rollingMomentCoefficient>
			<motorSpeedPubTopic>motor_speed/1</motorSpeedPubTopic>
			<rotorVelocitySlowdownSim>10</rotorVelocitySlowdownSim>
		</plugin>
	</gazebo>
	<gazebo reference="xxx/rotor_1">
		<material>Gazebo/Blue</material>
	</gazebo>
	<joint name="xxx/rotor_2_joint" type="continuous">
		<origin rpy="0    0 0" xyz="-0.186195461814 0.1075 0.037" />
		<axis xyz="0 0 1" />
		<!-- TODO(ff): not currently set because it's not yet supported -->
		<!-- <limit effort="2000" velocity="${max_rot_velocity}" /> -->
		<parent link="xxx/x1/base_link" />
		<child link="xxx/rotor_2" />
	</joint>
	<link name="xxx/rotor_2">
		<inertial>
			<mass value="0.005" />
			<!-- [kg] -->
			<inertia ixx="9.7499961e-07" ixy="0.0" ixz="0.0" iyy="4.1704149985e-05"
				iyz="0.0" izz="4.2604149625e-05" />
		</inertial>
		<visual>
			<geometry>
				<!-- <cylinder length="0.5" radius="${radius_rotor}"/> -->
				<!-- [m] -->
				<mesh filename="package://rotors_description/meshes/propeller_ccw.dae"
					scale="0.1 0.1 0.1" />
				<!-- The propeller meshes have a radius of 1m -->
				<!-- <box size="${2*radius_rotor} 0.01 0.005"/> -->
			</geometry>
		</visual>
		<collision>
			<geometry>
				<cylinder length="0.05" radius="0.1" />
				<!-- [m] -->
			</geometry>
		</collision>
	</link>
	<gazebo>
		<plugin filename="librotors_gazebo_motor_model.so" name="xxx_back_left_motor_model">
			<robotNamespace>xxx</robotNamespace>
			<jointName>xxx/rotor_2_joint</jointName>
			<linkName>xxx/rotor_2</linkName>
			<turningDirection>ccw</turningDirection>
			<timeConstantUp>0.0125</timeConstantUp>
			<timeConstantDown>0.025</timeConstantDown>
			<maxRotVelocity>838</maxRotVelocity>
			<motorConstant>8.54858e-06</motorConstant>
			<momentConstant>0.016</momentConstant>
			<commandSubTopic>gazebo/command/motor_speed</commandSubTopic>
			<motorNumber>2</motorNumber>
			<rotorDragCoefficient>8.06428e-05</rotorDragCoefficient>
			<rollingMomentCoefficient>1e-06</rollingMomentCoefficient>
			<motorSpeedPubTopic>motor_speed/2</motorSpeedPubTopic>
			<rotorVelocitySlowdownSim>10</rotorVelocitySlowdownSim>
		</plugin>
	</gazebo>
	<gazebo reference="xxx/rotor_2">
		<material>Gazebo/Blue</material>
	</gazebo>
	<joint name="xxx/rotor_3_joint" type="continuous">
		<origin rpy="0    0 0" xyz="-0.186195461814 -0.1075 0.037" />
		<axis xyz="0 0 1" />
		<!-- TODO(ff): not currently set because it's not yet supported -->
		<!-- <limit effort="2000" velocity="${max_rot_velocity}" /> -->
		<parent link="xxx/x1/base_link" />
		<child link="xxx/rotor_3" />
	</joint>
	<link name="xxx/rotor_3">
		<inertial>
			<mass value="0.005" />
			<!-- [kg] -->
			<inertia ixx="9.7499961e-07" ixy="0.0" ixz="0.0" iyy="4.1704149985e-05"
				iyz="0.0" izz="4.2604149625e-05" />
		</inertial>
		<visual>
			<geometry>
				<!-- <cylinder length="0.5" radius="${radius_rotor}"/> -->
				<!-- [m] -->
				<mesh filename="package://rotors_description/meshes/propeller_cw.dae"
					scale="0.1 0.1 0.1" />
				<!-- The propeller meshes have a radius of 1m -->
				<!-- <box size="${2*radius_rotor} 0.01 0.005"/> -->
			</geometry>
		</visual>
		<collision>
			<geometry>
				<cylinder length="0.05" radius="0.1" />
				<!-- [m] -->
			</geometry>
		</collision>
	</link>
	<gazebo>
		<plugin filename="librotors_gazebo_motor_model.so" name="xxx_back_right_motor_model">
			<robotNamespace>xxx</robotNamespace>
			<jointName>xxx/rotor_3_joint</jointName>
			<linkName>xxx/rotor_3</linkName>
			<turningDirection>cw</turningDirection>
			<timeConstantUp>0.0125</timeConstantUp>
			<timeConstantDown>0.025</timeConstantDown>
			<maxRotVelocity>838</maxRotVelocity>
			<motorConstant>8.54858e-06</motorConstant>
			<momentConstant>0.016</momentConstant>
			<commandSubTopic>gazebo/command/motor_speed</commandSubTopic>
			<motorNumber>3</motorNumber>
			<rotorDragCoefficient>8.06428e-05</rotorDragCoefficient>
			<rollingMomentCoefficient>1e-06</rollingMomentCoefficient>
			<motorSpeedPubTopic>motor_speed/3</motorSpeedPubTopic>
			<rotorVelocitySlowdownSim>10</rotorVelocitySlowdownSim>
		</plugin>
	</gazebo>
	<gazebo reference="xxx/rotor_3">
		<material>Gazebo/Blue</material>
	</gazebo>
	<joint name="xxx/rotor_4_joint" type="continuous">
		<origin rpy="0 0 0" xyz="0 -0.215 0.037" />
		<axis xyz="0 0 1" />
		<!-- TODO(ff): not currently set because it's not yet supported -->
		<!-- <limit effort="2000" velocity="${max_rot_velocity}" /> -->
		<parent link="xxx/x1/base_link" />
		<child link="xxx/rotor_4" />
	</joint>
	<link name="xxx/rotor_4">
		<inertial>
			<mass value="0.005" />
			<!-- [kg] -->
			<inertia ixx="9.7499961e-07" ixy="0.0" ixz="0.0" iyy="4.1704149985e-05"
				iyz="0.0" izz="4.2604149625e-05" />
		</inertial>
		<visual>
			<geometry>
				<!-- <cylinder length="0.5" radius="${radius_rotor}"/> -->
				<!-- [m] -->
				<mesh filename="package://rotors_description/meshes/propeller_ccw.dae"
					scale="0.1 0.1 0.1" />
				<!-- The propeller meshes have a radius of 1m -->
				<!-- <box size="${2*radius_rotor} 0.01 0.005"/> -->
			</geometry>
		</visual>
		<collision>
			<geometry>
				<cylinder length="0.05" radius="0.1" />
				<!-- [m] -->
			</geometry>
		</collision>
	</link>
	<gazebo>
		<plugin filename="librotors_gazebo_motor_model.so" name="xxx_right_motor_model">
			<robotNamespace>xxx</robotNamespace>
			<jointName>xxx/rotor_4_joint</jointName>
			<linkName>xxx/rotor_4</linkName>
			<turningDirection>ccw</turningDirection>
			<timeConstantUp>0.0125</timeConstantUp>
			<timeConstantDown>0.025</timeConstantDown>
			<maxRotVelocity>838</maxRotVelocity>
			<motorConstant>8.54858e-06</motorConstant>
			<momentConstant>0.016</momentConstant>
			<commandSubTopic>gazebo/command/motor_speed</commandSubTopic>
			<motorNumber>4</motorNumber>
			<rotorDragCoefficient>8.06428e-05</rotorDragCoefficient>
			<rollingMomentCoefficient>1e-06</rollingMomentCoefficient>
			<motorSpeedPubTopic>motor_speed/4</motorSpeedPubTopic>
			<rotorVelocitySlowdownSim>10</rotorVelocitySlowdownSim>
		</plugin>
	</gazebo>
	<gazebo reference="xxx/rotor_4">
		<material>Gazebo/Blue</material>
	</gazebo>
	<joint name="xxx/rotor_5_joint" type="continuous">
		<origin rpy="0    0 0" xyz="0.186195461814 -0.1075 0.037" />
		<axis xyz="0 0 1" />
		<!-- TODO(ff): not currently set because it's not yet supported -->
		<!-- <limit effort="2000" velocity="${max_rot_velocity}" /> -->
		<parent link="xxx/x1/base_link" />
		<child link="xxx/rotor_5" />
	</joint>
	<link name="xxx/rotor_5">
		<inertial>
			<mass value="0.005" />
			<!-- [kg] -->
			<inertia ixx="9.7499961e-07" ixy="0.0" ixz="0.0" iyy="4.1704149985e-05"
				iyz="0.0" izz="4.2604149625e-05" />
		</inertial>
		<visual>
			<geometry>
				<!-- <cylinder length="0.5" radius="${radius_rotor}"/> -->
				<!-- [m] -->
				<mesh filename="package://rotors_description/meshes/propeller_cw.dae"
					scale="0.1 0.1 0.1" />
				<!-- The propeller meshes have a radius of 1m -->
				<!-- <box size="${2*radius_rotor} 0.01 0.005"/> -->
			</geometry>
		</visual>
		<collision>
			<geometry>
				<cylinder length="0.05" radius="0.1" />
				<!-- [m] -->
			</geometry>
		</collision>
	</link>
	<gazebo>
		<plugin filename="librotors_gazebo_motor_model.so" name="xxx_front_right_motor_model">
			<robotNamespace>xxx</robotNamespace>
			<jointName>xxx/rotor_5_joint</jointName>
			<linkName>xxx/rotor_5</linkName>
			<turningDirection>cw</turningDirection>
			<timeConstantUp>0.0125</timeConstantUp>
			<timeConstantDown>0.025</timeConstantDown>
			<maxRotVelocity>838</maxRotVelocity>
			<motorConstant>8.54858e-06</motorConstant>
			<momentConstant>0.016</momentConstant>
			<commandSubTopic>gazebo/command/motor_speed</commandSubTopic>
			<motorNumber>5</motorNumber>
			<rotorDragCoefficient>8.06428e-05</rotorDragCoefficient>
			<rollingMomentCoefficient>1e-06</rollingMomentCoefficient>
			<motorSpeedPubTopic>motor_speed/5</motorSpeedPubTopic>
			<rotorVelocitySlowdownSim>10</rotorVelocitySlowdownSim>
		</plugin>
	</gazebo>
	<gazebo reference="xxx/rotor_5">
		<material>Gazebo/Red</material>
	</gazebo>
	<joint name="formation_joint_x1" type="revolute">
		<parent link="base_link" />
		<child link="xxx/x1/base_link" />
		<origin rpy="0 0 0" xyz="0.0 1.5 0.3" />
		<axis xyz="0.0 1.5 0.3" />
		<limit effort="1000.0" lower="-0.001" upper="0.001" velocity="0.01" />
		<dynamics damping="0" />
	</joint>
	<!-- Included URDF Files -->
	<!-- <origin xyz="${ox} ${oy} ${oz}" rpy="${ophi} ${otheta} ${opsi}" /> -->
	<!-- Instantiate multirotor_base_macro once -->
	<link name="xxx/x2/base_link" />
	<joint name="xxx/x2/base_joint" type="fixed">
		<origin rpy="0 0 0" xyz="0 0 0" />
		<parent link="xxx/x2/base_link" />
		<child link="xxx/x2/base_link_inertia" />
	</joint>
	<link name="xxx/x2/base_link_inertia">
		<inertial>
			<mass value="1.5" />
			<!-- [kg] -->
			<origin xyz="0 0 0" />
			<inertia ixx="0.0347563" ixy="0.0" ixz="0.0" iyy="0.0458929"
				iyz="0.0" izz="0.0977" />
		</inertial>
		<visual>
			<origin rpy="0 0 0" xyz="0 0 0" />
			<geometry>
				<mesh filename="package://rotors_description/meshes/firefly.dae"
					scale="1 1 1" />
			</geometry>
		</visual>
		<collision>
			<origin rpy="0 0 0" xyz="0 0 0" />
			<geometry>
				<box size="0.1 0.1 0.16" />
				<!-- [m] [m] [m] -->
			</geometry>
		</collision>
	</link>
	<!-- Instantiate rotors -->
	<joint name="xxx/rotor_6_joint" type="continuous">
		<origin rpy="0 0    0" xyz="0.186195461814 0.1075 0.037" />
		<axis xyz="0 0 1" />
		<!-- TODO(ff): not currently set because it's not yet supported -->
		<!-- <limit effort="2000" velocity="${max_rot_velocity}" /> -->
		<parent link="xxx/x2/base_link" />
		<child link="xxx/rotor_6" />
	</joint>
	<link name="xxx/rotor_6">
		<inertial>
			<mass value="0.005" />
			<!-- [kg] -->
			<inertia ixx="9.7499961e-07" ixy="0.0" ixz="0.0" iyy="4.1704149985e-05"
				iyz="0.0" izz="4.2604149625e-05" />
		</inertial>
		<visual>
			<geometry>
				<!-- <cylinder length="0.5" radius="${radius_rotor}"/> -->
				<!-- [m] -->
				<mesh filename="package://rotors_description/meshes/propeller_ccw.dae"
					scale="0.1 0.1 0.1" />
				<!-- The propeller meshes have a radius of 1m -->
				<!-- <box size="${2*radius_rotor} 0.01 0.005"/> -->
			</geometry>
		</visual>
		<collision>
			<geometry>
				<cylinder length="0.05" radius="0.1" />
				<!-- [m] -->
			</geometry>
		</collision>
	</link>
	<gazebo>
		<plugin filename="librotors_gazebo_motor_model.so" name="xxx_front_left_motor_model">
			<robotNamespace>xxx</robotNamespace>
			<jointName>xxx/rotor_6_joint</jointName>
			<linkName>xxx/rotor_6</linkName>
			<turningDirection>ccw</turningDirection>
			<timeConstantUp>0.0125</timeConstantUp>
			<timeConstantDown>0.025</timeConstantDown>
			<maxRotVelocity>838</maxRotVelocity>
			<motorConstant>8.54858e-06</motorConstant>
			<momentConstant>0.016</momentConstant>
			<commandSubTopic>gazebo/command/motor_speed</commandSubTopic>
			<motorNumber>6</motorNumber>
			<rotorDragCoefficient>8.06428e-05</rotorDragCoefficient>
			<rollingMomentCoefficient>1e-06</rollingMomentCoefficient>
			<motorSpeedPubTopic>motor_speed/6</motorSpeedPubTopic>
			<rotorVelocitySlowdownSim>10</rotorVelocitySlowdownSim>
		</plugin>
	</gazebo>
	<gazebo reference="xxx/rotor_6">
		<material>Gazebo/Red</material>
	</gazebo>
	<joint name="xxx/rotor_7_joint" type="continuous">
		<origin rpy="0 0 0" xyz="0 0.215 0.037" />
		<axis xyz="0 0 1" />
		<!-- TODO(ff): not currently set because it's not yet supported -->
		<!-- <limit effort="2000" velocity="${max_rot_velocity}" /> -->
		<parent link="xxx/x2/base_link" />
		<child link="xxx/rotor_7" />
	</joint>
	<link name="xxx/rotor_7">
		<inertial>
			<mass value="0.005" />
			<!-- [kg] -->
			<inertia ixx="9.7499961e-07" ixy="0.0" ixz="0.0" iyy="4.1704149985e-05"
				iyz="0.0" izz="4.2604149625e-05" />
		</inertial>
		<visual>
			<geometry>
				<!-- <cylinder length="0.5" radius="${radius_rotor}"/> -->
				<!-- [m] -->
				<mesh filename="package://rotors_description/meshes/propeller_cw.dae"
					scale="0.1 0.1 0.1" />
				<!-- The propeller meshes have a radius of 1m -->
				<!-- <box size="${2*radius_rotor} 0.01 0.005"/> -->
			</geometry>
		</visual>
		<collision>
			<geometry>
				<cylinder length="0.05" radius="0.1" />
				<!-- [m] -->
			</geometry>
		</collision>
	</link>
	<gazebo>
		<plugin filename="librotors_gazebo_motor_model.so" name="xxx_left_motor_model">
			<robotNamespace>xxx</robotNamespace>
			<jointName>xxx/rotor_7_joint</jointName>
			<linkName>xxx/rotor_7</linkName>
			<turningDirection>cw</turningDirection>
			<timeConstantUp>0.0125</timeConstantUp>
			<timeConstantDown>0.025</timeConstantDown>
			<maxRotVelocity>838</maxRotVelocity>
			<motorConstant>8.54858e-06</motorConstant>
			<momentConstant>0.016</momentConstant>
			<commandSubTopic>gazebo/command/motor_speed</commandSubTopic>
			<motorNumber>7</motorNumber>
			<rotorDragCoefficient>8.06428e-05</rotorDragCoefficient>
			<rollingMomentCoefficient>1e-06</rollingMomentCoefficient>
			<motorSpeedPubTopic>motor_speed/7</motorSpeedPubTopic>
			<rotorVelocitySlowdownSim>10</rotorVelocitySlowdownSim>
		</plugin>
	</gazebo>
	<gazebo reference="xxx/rotor_7">
		<material>Gazebo/Blue</material>
	</gazebo>
	<joint name="xxx/rotor_8_joint" type="continuous">
		<origin rpy="0    0 0" xyz="-0.186195461814 0.1075 0.037" />
		<axis xyz="0 0 1" />
		<!-- TODO(ff): not currently set because it's not yet supported -->
		<!-- <limit effort="2000" velocity="${max_rot_velocity}" /> -->
		<parent link="xxx/x2/base_link" />
		<child link="xxx/rotor_8" />
	</joint>
	<link name="xxx/rotor_8">
		<inertial>
			<mass value="0.005" />
			<!-- [kg] -->
			<inertia ixx="9.7499961e-07" ixy="0.0" ixz="0.0" iyy="4.1704149985e-05"
				iyz="0.0" izz="4.2604149625e-05" />
		</inertial>
		<visual>
			<geometry>
				<!-- <cylinder length="0.5" radius="${radius_rotor}"/> -->
				<!-- [m] -->
				<mesh filename="package://rotors_description/meshes/propeller_ccw.dae"
					scale="0.1 0.1 0.1" />
				<!-- The propeller meshes have a radius of 1m -->
				<!-- <box size="${2*radius_rotor} 0.01 0.005"/> -->
			</geometry>
		</visual>
		<collision>
			<geometry>
				<cylinder length="0.05" radius="0.1" />
				<!-- [m] -->
			</geometry>
		</collision>
	</link>
	<gazebo>
		<plugin filename="librotors_gazebo_motor_model.so" name="xxx_back_left_motor_model">
			<robotNamespace>xxx</robotNamespace>
			<jointName>xxx/rotor_8_joint</jointName>
			<linkName>xxx/rotor_8</linkName>
			<turningDirection>ccw</turningDirection>
			<timeConstantUp>0.0125</timeConstantUp>
			<timeConstantDown>0.025</timeConstantDown>
			<maxRotVelocity>838</maxRotVelocity>
			<motorConstant>8.54858e-06</motorConstant>
			<momentConstant>0.016</momentConstant>
			<commandSubTopic>gazebo/command/motor_speed</commandSubTopic>
			<motorNumber>8</motorNumber>
			<rotorDragCoefficient>8.06428e-05</rotorDragCoefficient>
			<rollingMomentCoefficient>1e-06</rollingMomentCoefficient>
			<motorSpeedPubTopic>motor_speed/8</motorSpeedPubTopic>
			<rotorVelocitySlowdownSim>10</rotorVelocitySlowdownSim>
		</plugin>
	</gazebo>
	<gazebo reference="xxx/rotor_8">
		<material>Gazebo/Blue</material>
	</gazebo>
	<joint name="xxx/rotor_9_joint" type="continuous">
		<origin rpy="0    0 0" xyz="-0.186195461814 -0.1075 0.037" />
		<axis xyz="0 0 1" />
		<!-- TODO(ff): not currently set because it's not yet supported -->
		<!-- <limit effort="2000" velocity="${max_rot_velocity}" /> -->
		<parent link="xxx/x2/base_link" />
		<child link="xxx/rotor_9" />
	</joint>
	<link name="xxx/rotor_9">
		<inertial>
			<mass value="0.005" />
			<!-- [kg] -->
			<inertia ixx="9.7499961e-07" ixy="0.0" ixz="0.0" iyy="4.1704149985e-05"
				iyz="0.0" izz="4.2604149625e-05" />
		</inertial>
		<visual>
			<geometry>
				<!-- <cylinder length="0.5" radius="${radius_rotor}"/> -->
				<!-- [m] -->
				<mesh filename="package://rotors_description/meshes/propeller_cw.dae"
					scale="0.1 0.1 0.1" />
				<!-- The propeller meshes have a radius of 1m -->
				<!-- <box size="${2*radius_rotor} 0.01 0.005"/> -->
			</geometry>
		</visual>
		<collision>
			<geometry>
				<cylinder length="0.05" radius="0.1" />
				<!-- [m] -->
			</geometry>
		</collision>
	</link>
	<gazebo>
		<plugin filename="librotors_gazebo_motor_model.so" name="xxx_back_right_motor_model">
			<robotNamespace>xxx</robotNamespace>
			<jointName>xxx/rotor_9_joint</jointName>
			<linkName>xxx/rotor_9</linkName>
			<turningDirection>cw</turningDirection>
			<timeConstantUp>0.0125</timeConstantUp>
			<timeConstantDown>0.025</timeConstantDown>
			<maxRotVelocity>838</maxRotVelocity>
			<motorConstant>8.54858e-06</motorConstant>
			<momentConstant>0.016</momentConstant>
			<commandSubTopic>gazebo/command/motor_speed</commandSubTopic>
			<motorNumber>9</motorNumber>
			<rotorDragCoefficient>8.06428e-05</rotorDragCoefficient>
			<rollingMomentCoefficient>1e-06</rollingMomentCoefficient>
			<motorSpeedPubTopic>motor_speed/9</motorSpeedPubTopic>
			<rotorVelocitySlowdownSim>10</rotorVelocitySlowdownSim>
		</plugin>
	</gazebo>
	<gazebo reference="xxx/rotor_9">
		<material>Gazebo/Blue</material>
	</gazebo>
	<joint name="xxx/rotor_10_joint" type="continuous">
		<origin rpy="0 0 0" xyz="0 -0.215 0.037" />
		<axis xyz="0 0 1" />
		<!-- TODO(ff): not currently set because it's not yet supported -->
		<!-- <limit effort="2000" velocity="${max_rot_velocity}" /> -->
		<parent link="xxx/x2/base_link" />
		<child link="xxx/rotor_10" />
	</joint>
	<link name="xxx/rotor_10">
		<inertial>
			<mass value="0.005" />
			<!-- [kg] -->
			<inertia ixx="9.7499961e-07" ixy="0.0" ixz="0.0" iyy="4.1704149985e-05"
				iyz="0.0" izz="4.2604149625e-05" />
		</inertial>
		<visual>
			<geometry>
				<!-- <cylinder length="0.5" radius="${radius_rotor}"/> -->
				<!-- [m] -->
				<mesh filename="package://rotors_description/meshes/propeller_ccw.dae"
					scale="0.1 0.1 0.1" />
				<!-- The propeller meshes have a radius of 1m -->
				<!-- <box size="${2*radius_rotor} 0.01 0.005"/> -->
			</geometry>
		</visual>
		<collision>
			<geometry>
				<cylinder length="0.05" radius="0.1" />
				<!-- [m] -->
			</geometry>
		</collision>
	</link>
	<gazebo>
		<plugin filename="librotors_gazebo_motor_model.so" name="xxx_right_motor_model">
			<robotNamespace>xxx</robotNamespace>
			<jointName>xxx/rotor_10_joint</jointName>
			<linkName>xxx/rotor_10</linkName>
			<turningDirection>ccw</turningDirection>
			<timeConstantUp>0.0125</timeConstantUp>
			<timeConstantDown>0.025</timeConstantDown>
			<maxRotVelocity>838</maxRotVelocity>
			<motorConstant>8.54858e-06</motorConstant>
			<momentConstant>0.016</momentConstant>
			<commandSubTopic>gazebo/command/motor_speed</commandSubTopic>
			<motorNumber>10</motorNumber>
			<rotorDragCoefficient>8.06428e-05</rotorDragCoefficient>
			<rollingMomentCoefficient>1e-06</rollingMomentCoefficient>
			<motorSpeedPubTopic>motor_speed/10</motorSpeedPubTopic>
			<rotorVelocitySlowdownSim>10</rotorVelocitySlowdownSim>
		</plugin>
	</gazebo>
	<gazebo reference="xxx/rotor_10">
		<material>Gazebo/Blue</material>
	</gazebo>
	<joint name="xxx/rotor_11_joint" type="continuous">
		<origin rpy="0    0 0" xyz="0.186195461814 -0.1075 0.037" />
		<axis xyz="0 0 1" />
		<!-- TODO(ff): not currently set because it's not yet supported -->
		<!-- <limit effort="2000" velocity="${max_rot_velocity}" /> -->
		<parent link="xxx/x2/base_link" />
		<child link="xxx/rotor_11" />
	</joint>
	<link name="xxx/rotor_11">
		<inertial>
			<mass value="0.005" />
			<!-- [kg] -->
			<inertia ixx="9.7499961e-07" ixy="0.0" ixz="0.0" iyy="4.1704149985e-05"
				iyz="0.0" izz="4.2604149625e-05" />
		</inertial>
		<visual>
			<geometry>
				<!-- <cylinder length="0.5" radius="${radius_rotor}"/> -->
				<!-- [m] -->
				<mesh filename="package://rotors_description/meshes/propeller_cw.dae"
					scale="0.1 0.1 0.1" />
				<!-- The propeller meshes have a radius of 1m -->
				<!-- <box size="${2*radius_rotor} 0.01 0.005"/> -->
			</geometry>
		</visual>
		<collision>
			<geometry>
				<cylinder length="0.05" radius="0.1" />
				<!-- [m] -->
			</geometry>
		</collision>
	</link>
	<gazebo>
		<plugin filename="librotors_gazebo_motor_model.so" name="xxx_front_right_motor_model">
			<robotNamespace>xxx</robotNamespace>
			<jointName>xxx/rotor_11_joint</jointName>
			<linkName>xxx/rotor_11</linkName>
			<turningDirection>cw</turningDirection>
			<timeConstantUp>0.0125</timeConstantUp>
			<timeConstantDown>0.025</timeConstantDown>
			<maxRotVelocity>838</maxRotVelocity>
			<motorConstant>8.54858e-06</motorConstant>
			<momentConstant>0.016</momentConstant>
			<commandSubTopic>gazebo/command/motor_speed</commandSubTopic>
			<motorNumber>11</motorNumber>
			<rotorDragCoefficient>8.06428e-05</rotorDragCoefficient>
			<rollingMomentCoefficient>1e-06</rollingMomentCoefficient>
			<motorSpeedPubTopic>motor_speed/11</motorSpeedPubTopic>
			<rotorVelocitySlowdownSim>10</rotorVelocitySlowdownSim>
		</plugin>
	</gazebo>
	<gazebo reference="xxx/rotor_11">
		<material>Gazebo/Red</material>
	</gazebo>
	<joint name="formation_joint_x2" type="revolute">
		<child link="xxx/x2/base_link" />
		<parent link="base_link" />
		<origin rpy="0 0 0" xyz="0.0 -1.5 0.3" />
		<axis xyz="0.0 -1.5 0.3" />
		<limit effort="1000.0" lower="-0.001" upper="0.001" velocity="0.01" />
		<dynamics damping="0" />
	</joint>
	<!-- Included URDF Files -->
	<!-- <origin xyz="${ox} ${oy} ${oz}" rpy="${ophi} ${otheta} ${opsi}" /> -->
	<!-- Instantiate multirotor_base_macro once -->
	<link name="xxx/x3/base_link" />
	<joint name="xxx/x3/base_joint" type="fixed">
		<origin rpy="0 0 0" xyz="0 0 0" />
		<parent link="xxx/x3/base_link" />
		<child link="xxx/x3/base_link_inertia" />
	</joint>
	<link name="xxx/x3/base_link_inertia">
		<inertial>
			<mass value="1.5" />
			<!-- [kg] -->
			<origin xyz="0 0 0" />
			<inertia ixx="0.0347563" ixy="0.0" ixz="0.0" iyy="0.0458929"
				iyz="0.0" izz="0.0977" />
		</inertial>
		<visual>
			<origin rpy="0 0 0" xyz="0 0 0" />
			<geometry>
				<mesh filename="package://rotors_description/meshes/firefly.dae"
					scale="1 1 1" />
			</geometry>
		</visual>
		<collision>
			<origin rpy="0 0 0" xyz="0 0 0" />
			<geometry>
				<box size="0.1 0.1 0.16" />
				<!-- [m] [m] [m] -->
			</geometry>
		</collision>
	</link>
	<!-- Instantiate rotors -->
	<joint name="xxx/rotor_12_joint" type="continuous">
		<origin rpy="0 0    0" xyz="0.186195461814 0.1075 0.037" />
		<axis xyz="0 0 1" />
		<!-- TODO(ff): not currently set because it's not yet supported -->
		<!-- <limit effort="2000" velocity="${max_rot_velocity}" /> -->
		<parent link="xxx/x3/base_link" />
		<child link="xxx/rotor_12" />
	</joint>
	<link name="xxx/rotor_12">
		<inertial>
			<mass value="0.005" />
			<!-- [kg] -->
			<inertia ixx="9.7499961e-07" ixy="0.0" ixz="0.0" iyy="4.1704149985e-05"
				iyz="0.0" izz="4.2604149625e-05" />
		</inertial>
		<visual>
			<geometry>
				<!-- <cylinder length="0.5" radius="${radius_rotor}"/> -->
				<!-- [m] -->
				<mesh filename="package://rotors_description/meshes/propeller_ccw.dae"
					scale="0.1 0.1 0.1" />
				<!-- The propeller meshes have a radius of 1m -->
				<!-- <box size="${2*radius_rotor} 0.01 0.005"/> -->
			</geometry>
		</visual>
		<collision>
			<geometry>
				<cylinder length="0.05" radius="0.1" />
				<!-- [m] -->
			</geometry>
		</collision>
	</link>
	<gazebo>
		<plugin filename="librotors_gazebo_motor_model.so" name="xxx_front_left_motor_model">
			<robotNamespace>xxx</robotNamespace>
			<jointName>xxx/rotor_12_joint</jointName>
			<linkName>xxx/rotor_12</linkName>
			<turningDirection>ccw</turningDirection>
			<timeConstantUp>0.0125</timeConstantUp>
			<timeConstantDown>0.025</timeConstantDown>
			<maxRotVelocity>838</maxRotVelocity>
			<motorConstant>8.54858e-06</motorConstant>
			<momentConstant>0.016</momentConstant>
			<commandSubTopic>gazebo/command/motor_speed</commandSubTopic>
			<motorNumber>12</motorNumber>
			<rotorDragCoefficient>8.06428e-05</rotorDragCoefficient>
			<rollingMomentCoefficient>1e-06</rollingMomentCoefficient>
			<motorSpeedPubTopic>motor_speed/12</motorSpeedPubTopic>
			<rotorVelocitySlowdownSim>10</rotorVelocitySlowdownSim>
		</plugin>
	</gazebo>
	<gazebo reference="xxx/rotor_12">
		<material>Gazebo/Red</material>
	</gazebo>
	<joint name="xxx/rotor_13_joint" type="continuous">
		<origin rpy="0 0 0" xyz="0 0.215 0.037" />
		<axis xyz="0 0 1" />
		<!-- TODO(ff): not currently set because it's not yet supported -->
		<!-- <limit effort="2000" velocity="${max_rot_velocity}" /> -->
		<parent link="xxx/x3/base_link" />
		<child link="xxx/rotor_13" />
	</joint>
	<link name="xxx/rotor_13">
		<inertial>
			<mass value="0.005" />
			<!-- [kg] -->
			<inertia ixx="9.7499961e-07" ixy="0.0" ixz="0.0" iyy="4.1704149985e-05"
				iyz="0.0" izz="4.2604149625e-05" />
		</inertial>
		<visual>
			<geometry>
				<!-- <cylinder length="0.5" radius="${radius_rotor}"/> -->
				<!-- [m] -->
				<mesh filename="package://rotors_description/meshes/propeller_cw.dae"
					scale="0.1 0.1 0.1" />
				<!-- The propeller meshes have a radius of 1m -->
				<!-- <box size="${2*radius_rotor} 0.01 0.005"/> -->
			</geometry>
		</visual>
		<collision>
			<geometry>
				<cylinder length="0.05" radius="0.1" />
				<!-- [m] -->
			</geometry>
		</collision>
	</link>
	<gazebo>
		<plugin filename="librotors_gazebo_motor_model.so" name="xxx_left_motor_model">
			<robotNamespace>xxx</robotNamespace>
			<jointName>xxx/rotor_13_joint</jointName>
			<linkName>xxx/rotor_13</linkName>
			<turningDirection>cw</turningDirection>
			<timeConstantUp>0.0125</timeConstantUp>
			<timeConstantDown>0.025</timeConstantDown>
			<maxRotVelocity>838</maxRotVelocity>
			<motorConstant>8.54858e-06</motorConstant>
			<momentConstant>0.016</momentConstant>
			<commandSubTopic>gazebo/command/motor_speed</commandSubTopic>
			<motorNumber>13</motorNumber>
			<rotorDragCoefficient>8.06428e-05</rotorDragCoefficient>
			<rollingMomentCoefficient>1e-06</rollingMomentCoefficient>
			<motorSpeedPubTopic>motor_speed/13</motorSpeedPubTopic>
			<rotorVelocitySlowdownSim>10</rotorVelocitySlowdownSim>
		</plugin>
	</gazebo>
	<gazebo reference="xxx/rotor_13">
		<material>Gazebo/Blue</material>
	</gazebo>
	<joint name="xxx/rotor_14_joint" type="continuous">
		<origin rpy="0    0 0" xyz="-0.186195461814 0.1075 0.037" />
		<axis xyz="0 0 1" />
		<!-- TODO(ff): not currently set because it's not yet supported -->
		<!-- <limit effort="2000" velocity="${max_rot_velocity}" /> -->
		<parent link="xxx/x3/base_link" />
		<child link="xxx/rotor_14" />
	</joint>
	<link name="xxx/rotor_14">
		<inertial>
			<mass value="0.005" />
			<!-- [kg] -->
			<inertia ixx="9.7499961e-07" ixy="0.0" ixz="0.0" iyy="4.1704149985e-05"
				iyz="0.0" izz="4.2604149625e-05" />
		</inertial>
		<visual>
			<geometry>
				<!-- <cylinder length="0.5" radius="${radius_rotor}"/> -->
				<!-- [m] -->
				<mesh filename="package://rotors_description/meshes/propeller_ccw.dae"
					scale="0.1 0.1 0.1" />
				<!-- The propeller meshes have a radius of 1m -->
				<!-- <box size="${2*radius_rotor} 0.01 0.005"/> -->
			</geometry>
		</visual>
		<collision>
			<geometry>
				<cylinder length="0.05" radius="0.1" />
				<!-- [m] -->
			</geometry>
		</collision>
	</link>
	<gazebo>
		<plugin filename="librotors_gazebo_motor_model.so" name="xxx_back_left_motor_model">
			<robotNamespace>xxx</robotNamespace>
			<jointName>xxx/rotor_14_joint</jointName>
			<linkName>xxx/rotor_14</linkName>
			<turningDirection>ccw</turningDirection>
			<timeConstantUp>0.0125</timeConstantUp>
			<timeConstantDown>0.025</timeConstantDown>
			<maxRotVelocity>838</maxRotVelocity>
			<motorConstant>8.54858e-06</motorConstant>
			<momentConstant>0.016</momentConstant>
			<commandSubTopic>gazebo/command/motor_speed</commandSubTopic>
			<motorNumber>14</motorNumber>
			<rotorDragCoefficient>8.06428e-05</rotorDragCoefficient>
			<rollingMomentCoefficient>1e-06</rollingMomentCoefficient>
			<motorSpeedPubTopic>motor_speed/14</motorSpeedPubTopic>
			<rotorVelocitySlowdownSim>10</rotorVelocitySlowdownSim>
		</plugin>
	</gazebo>
	<gazebo reference="xxx/rotor_14">
		<material>Gazebo/Blue</material>
	</gazebo>
	<joint name="xxx/rotor_15_joint" type="continuous">
		<origin rpy="0    0 0" xyz="-0.186195461814 -0.1075 0.037" />
		<axis xyz="0 0 1" />
		<!-- TODO(ff): not currently set because it's not yet supported -->
		<!-- <limit effort="2000" velocity="${max_rot_velocity}" /> -->
		<parent link="xxx/x3/base_link" />
		<child link="xxx/rotor_15" />
	</joint>
	<link name="xxx/rotor_15">
		<inertial>
			<mass value="0.005" />
			<!-- [kg] -->
			<inertia ixx="9.7499961e-07" ixy="0.0" ixz="0.0" iyy="4.1704149985e-05"
				iyz="0.0" izz="4.2604149625e-05" />
		</inertial>
		<visual>
			<geometry>
				<!-- <cylinder length="0.5" radius="${radius_rotor}"/> -->
				<!-- [m] -->
				<mesh filename="package://rotors_description/meshes/propeller_cw.dae"
					scale="0.1 0.1 0.1" />
				<!-- The propeller meshes have a radius of 1m -->
				<!-- <box size="${2*radius_rotor} 0.01 0.005"/> -->
			</geometry>
		</visual>
		<collision>
			<geometry>
				<cylinder length="0.05" radius="0.1" />
				<!-- [m] -->
			</geometry>
		</collision>
	</link>
	<gazebo>
		<plugin filename="librotors_gazebo_motor_model.so" name="xxx_back_right_motor_model">
			<robotNamespace>xxx</robotNamespace>
			<jointName>xxx/rotor_15_joint</jointName>
			<linkName>xxx/rotor_15</linkName>
			<turningDirection>cw</turningDirection>
			<timeConstantUp>0.0125</timeConstantUp>
			<timeConstantDown>0.025</timeConstantDown>
			<maxRotVelocity>838</maxRotVelocity>
			<motorConstant>8.54858e-06</motorConstant>
			<momentConstant>0.016</momentConstant>
			<commandSubTopic>gazebo/command/motor_speed</commandSubTopic>
			<motorNumber>15</motorNumber>
			<rotorDragCoefficient>8.06428e-05</rotorDragCoefficient>
			<rollingMomentCoefficient>1e-06</rollingMomentCoefficient>
			<motorSpeedPubTopic>motor_speed/15</motorSpeedPubTopic>
			<rotorVelocitySlowdownSim>10</rotorVelocitySlowdownSim>
		</plugin>
	</gazebo>
	<gazebo reference="xxx/rotor_15">
		<material>Gazebo/Blue</material>
	</gazebo>
	<joint name="xxx/rotor_16_joint" type="continuous">
		<origin rpy="0 0 0" xyz="0 -0.215 0.037" />
		<axis xyz="0 0 1" />
		<!-- TODO(ff): not currently set because it's not yet supported -->
		<!-- <limit effort="2000" velocity="${max_rot_velocity}" /> -->
		<parent link="xxx/x3/base_link" />
		<child link="xxx/rotor_16" />
	</joint>
	<link name="xxx/rotor_16">
		<inertial>
			<mass value="0.005" />
			<!-- [kg] -->
			<inertia ixx="9.7499961e-07" ixy="0.0" ixz="0.0" iyy="4.1704149985e-05"
				iyz="0.0" izz="4.2604149625e-05" />
		</inertial>
		<visual>
			<geometry>
				<!-- <cylinder length="0.5" radius="${radius_rotor}"/> -->
				<!-- [m] -->
				<mesh filename="package://rotors_description/meshes/propeller_ccw.dae"
					scale="0.1 0.1 0.1" />
				<!-- The propeller meshes have a radius of 1m -->
				<!-- <box size="${2*radius_rotor} 0.01 0.005"/> -->
			</geometry>
		</visual>
		<collision>
			<geometry>
				<cylinder length="0.05" radius="0.1" />
				<!-- [m] -->
			</geometry>
		</collision>
	</link>
	<gazebo>
		<plugin filename="librotors_gazebo_motor_model.so" name="xxx_right_motor_model">
			<robotNamespace>xxx</robotNamespace>
			<jointName>xxx/rotor_16_joint</jointName>
			<linkName>xxx/rotor_16</linkName>
			<turningDirection>ccw</turningDirection>
			<timeConstantUp>0.0125</timeConstantUp>
			<timeConstantDown>0.025</timeConstantDown>
			<maxRotVelocity>838</maxRotVelocity>
			<motorConstant>8.54858e-06</motorConstant>
			<momentConstant>0.016</momentConstant>
			<commandSubTopic>gazebo/command/motor_speed</commandSubTopic>
			<motorNumber>16</motorNumber>
			<rotorDragCoefficient>8.06428e-05</rotorDragCoefficient>
			<rollingMomentCoefficient>1e-06</rollingMomentCoefficient>
			<motorSpeedPubTopic>motor_speed/16</motorSpeedPubTopic>
			<rotorVelocitySlowdownSim>10</rotorVelocitySlowdownSim>
		</plugin>
	</gazebo>
	<gazebo reference="xxx/rotor_16">
		<material>Gazebo/Blue</material>
	</gazebo>
	<joint name="xxx/rotor_17_joint" type="continuous">
		<origin rpy="0    0 0" xyz="0.186195461814 -0.1075 0.037" />
		<axis xyz="0 0 1" />
		<!-- TODO(ff): not currently set because it's not yet supported -->
		<!-- <limit effort="2000" velocity="${max_rot_velocity}" /> -->
		<parent link="xxx/x3/base_link" />
		<child link="xxx/rotor_17" />
	</joint>
	<link name="xxx/rotor_17">
		<inertial>
			<mass value="0.005" />
			<!-- [kg] -->
			<inertia ixx="9.7499961e-07" ixy="0.0" ixz="0.0" iyy="4.1704149985e-05"
				iyz="0.0" izz="4.2604149625e-05" />
		</inertial>
		<visual>
			<geometry>
				<!-- <cylinder length="0.5" radius="${radius_rotor}"/> -->
				<!-- [m] -->
				<mesh filename="package://rotors_description/meshes/propeller_cw.dae"
					scale="0.1 0.1 0.1" />
				<!-- The propeller meshes have a radius of 1m -->
				<!-- <box size="${2*radius_rotor} 0.01 0.005"/> -->
			</geometry>
		</visual>
		<collision>
			<geometry>
				<cylinder length="0.05" radius="0.1" />
				<!-- [m] -->
			</geometry>
		</collision>
	</link>
	<gazebo>
		<plugin filename="librotors_gazebo_motor_model.so" name="xxx_front_right_motor_model">
			<robotNamespace>xxx</robotNamespace>
			<jointName>xxx/rotor_17_joint</jointName>
			<linkName>xxx/rotor_17</linkName>
			<turningDirection>cw</turningDirection>
			<timeConstantUp>0.0125</timeConstantUp>
			<timeConstantDown>0.025</timeConstantDown>
			<maxRotVelocity>838</maxRotVelocity>
			<motorConstant>8.54858e-06</motorConstant>
			<momentConstant>0.016</momentConstant>
			<commandSubTopic>gazebo/command/motor_speed</commandSubTopic>
			<motorNumber>17</motorNumber>
			<rotorDragCoefficient>8.06428e-05</rotorDragCoefficient>
			<rollingMomentCoefficient>1e-06</rollingMomentCoefficient>
			<motorSpeedPubTopic>motor_speed/17</motorSpeedPubTopic>
			<rotorVelocitySlowdownSim>10</rotorVelocitySlowdownSim>
		</plugin>
	</gazebo>
	<gazebo reference="xxx/rotor_17">
		<material>Gazebo/Red</material>
	</gazebo>
	<joint name="formation_joint_x3" type="revolute">
		<parent link="base_link" />
		<child link="xxx/x3/base_link" />
		<origin rpy="0 0 0" xyz="0.0 0.0 0.3" />
		<axis xyz="0.0 0.0 0.3" />
		<limit effort="1000.0" lower="-0.001" upper="0.001" velocity="0.01" />
		<dynamics damping="0" />
	</joint>
	<!-- attach multirotor_base_plugin to the base_link -->
	<gazebo>
		<plugin filename="librotors_gazebo_multirotor_base_plugin.so"
			name="xxx_multirotor_base_plugin">
			<robotNamespace>xxx</robotNamespace>
			<linkName>xxx/x1/base_link</linkName>
			<rotorVelocitySlowdownSim>10</rotorVelocitySlowdownSim>
		</plugin>
	</gazebo>
	<!-- Mount an IMU providing ground truth. -->
	<!-- IMU link -->
	<link name="xxx/imugt_link">
		<inertial>
			<inertia ixx="0.00001" ixy="0.0" ixz="0.0" iyy="0.00001" iyz="0.0"
				izz="0.00001" />
			<mass value="1e-05" />
			<!-- [kg] -->
			<origin rpy="0 0 0" xyz="0 0 0" />
		</inertial>
	</link>
	<!-- IMU joint -->
	<joint name="xxx/imugt_joint" type="revolute">
		<origin rpy="0 0 0" xyz="0 0 0" />
		<parent link="base_link" />
		<child link="xxx/imugt_link" />
		<limit effort="0" lower="0" upper="0" velocity="0" />
	</joint>
	<gazebo>
		<plugin filename="librotors_gazebo_imu_plugin.so" name="rotors_gazebo_imugt_plugin">
			<!-- A good description of the IMU parameters can be found in the kalibr 
				documentation: https://github.com/ethz-asl/kalibr/wiki/IMU-Noise-Model-and-Intrinsics -->
			<robotNamespace>xxx</robotNamespace>
			<!-- (string, required): ros namespace in which the messages are published -->
			<linkName>xxx/imugt_link</linkName>
			<!-- (string, required): name of the body which holds the IMU sensor -->
			<imuTopic>ground_truth/imu</imuTopic>
			<!-- (string): name of the sensor output topic and prefix of service names 
				(defaults to imu) -->
			<gyroscopeNoiseDensity>0.0</gyroscopeNoiseDensity>
			<!-- Gyroscope noise density (two-sided spectrum) [rad/s/sqrt(Hz)] -->
			<gyroscopeRandomWalk>0.0</gyroscopeRandomWalk>
			<!-- Gyroscope bias random walk [rad/s/s/sqrt(Hz)] -->
			<gyroscopeBiasCorrelationTime>1000.0</gyroscopeBiasCorrelationTime>
			<!-- Gyroscope bias correlation time constant [s] -->
			<gyroscopeTurnOnBiasSigma>0.0</gyroscopeTurnOnBiasSigma>
			<!-- Gyroscope turn on bias standard deviation [rad/s] -->
			<accelerometerNoiseDensity>0.0</accelerometerNoiseDensity>
			<!-- Accelerometer noise density (two-sided spectrum) [m/s^2/sqrt(Hz)] -->
			<accelerometerRandomWalk>0.0</accelerometerRandomWalk>
			<!-- Accelerometer bias random walk. [m/s^2/s/sqrt(Hz)] -->
			<accelerometerBiasCorrelationTime>300.0</accelerometerBiasCorrelationTime>
			<!-- Accelerometer bias correlation time constant [s] -->
			<accelerometerTurnOnBiasSigma>0.0</accelerometerTurnOnBiasSigma>
			<!-- Accelerometer turn on bias standard deviation [m/s^2] -->
		</plugin>
	</gazebo>
	<!-- Mount a generic odometry sensor providing ground truth. -->
	<!-- odometry link -->
	<link name="xxx/odometry_sensorgt_link">
		<inertial>
			<inertia ixx="0.00001" ixy="0.0" ixz="0.0" iyy="0.00001" iyz="0.0"
				izz="0.00001" />
			<mass value="1e-05" />
			<!-- [kg] -->
		</inertial>
	</link>
	<!-- odometry joint -->
	<joint name="xxx/odometry_sensorgt_joint" type="revolute">
		<parent link="base_link" />
		<origin rpy="0.0 0.0 0.0" xyz="0.0 0.0 0.0" />
		<child link="xxx/odometry_sensorgt_link" />
		<limit effort="0" lower="0" upper="0" velocity="0" />
	</joint>
	<gazebo>
		<plugin filename="librotors_gazebo_odometry_plugin.so" name="odometry_sensorgt">
			<linkName>xxx/odometry_sensorgt_link</linkName>
			<robotNamespace>xxx</robotNamespace>
			<poseTopic>ground_truth/pose</poseTopic>
			<poseWithCovarianceTopic>ground_truth/pose_with_covariance</poseWithCovarianceTopic>
			<positionTopic>ground_truth/position</positionTopic>
			<transformTopic>ground_truth/transform</transformTopic>
			<odometryTopic>ground_truth/odometry</odometryTopic>
			<parentFrameId>world</parentFrameId>
			<!-- Use the scoped link name here. e.g. Model::link. -->
			<childFrameId>xxx/base_link</childFrameId>
			<measurementDivisor>1</measurementDivisor>
			<!-- only every (seq % measurementDivisor) == 0 measurement is published 
				[int] -->
			<measurementDelay>0</measurementDelay>
			<!-- time that measurement gets held back before it's published in [simulation 
				cycles (int)] -->
			<unknownDelay>0.0</unknownDelay>
			<!-- additional delay, that just gets added to the timestamp [s] -->
			<noiseNormalPosition>0 0 0</noiseNormalPosition>
			<!-- standard deviation of additive white gaussian noise [m] -->
			<noiseNormalQuaternion>0 0 0</noiseNormalQuaternion>
			<!-- standard deviation white gaussian noise [rad]: q_m = q*quaternionFromSmallAngleApproximation(noiseNormalQ) -->
			<noiseNormalLinearVelocity>0 0 0</noiseNormalLinearVelocity>
			<!-- standard deviation of additive white gaussian noise [m/s] -->
			<noiseNormalAngularVelocity>0 0 0</noiseNormalAngularVelocity>
			<!-- standard deviation of additive white gaussian noise [rad/s] -->
			<noiseUniformPosition>0 0 0</noiseUniformPosition>
			<!-- symmetric bounds of uniform noise [m] -->
			<noiseUniformQuaternion>0 0 0</noiseUniformQuaternion>
			<!-- symmetric bounds of uniform noise [rad], computation see above -->
			<noiseUniformLinearVelocity>0 0 0</noiseUniformLinearVelocity>
			<!-- symmetric bounds of uniform noise [m/s] -->
			<noiseUniformAngularVelocity>0 0 0</noiseUniformAngularVelocity>
			<!-- symmetric bounds of uniform noise [rad/s] -->
		</plugin>
	</gazebo>
</robot>
